[2025-04-24T15:37:08.273+0000] {local_task_job_runner.py:123} INFO - ::group::Pre task execution logs
[2025-04-24T15:37:08.281+0000] {taskinstance.py:2612} INFO - Dependencies all met for dep_context=non-requeueable deps ti=<TaskInstance: airflow_lab.load_data_to_snowflake manual__2025-04-24T15:37:00.247492+00:00 [queued]>
[2025-04-24T15:37:08.285+0000] {taskinstance.py:2612} INFO - Dependencies all met for dep_context=requeueable deps ti=<TaskInstance: airflow_lab.load_data_to_snowflake manual__2025-04-24T15:37:00.247492+00:00 [queued]>
[2025-04-24T15:37:08.285+0000] {taskinstance.py:2865} INFO - Starting attempt 1 of 1
[2025-04-24T15:37:08.290+0000] {taskinstance.py:2888} INFO - Executing <Task(_PythonDecoratedOperator): load_data_to_snowflake> on 2025-04-24 15:37:00.247492+00:00
[2025-04-24T15:37:08.293+0000] {warnings.py:112} WARNING - /home/***/.local/lib/python3.12/site-packages/***/task/task_runner/standard_task_runner.py:70: DeprecationWarning: This process (pid=1463) is multi-threaded, use of fork() may lead to deadlocks in the child.
  pid = os.fork()

[2025-04-24T15:37:08.294+0000] {standard_task_runner.py:72} INFO - Started process 1465 to run task
[2025-04-24T15:37:08.295+0000] {standard_task_runner.py:104} INFO - Running: ['***', 'tasks', 'run', '***_lab', 'load_data_to_snowflake', 'manual__2025-04-24T15:37:00.247492+00:00', '--job-id', '101', '--raw', '--subdir', 'DAGS_FOLDER/elt.py', '--cfg-path', '/tmp/tmp7266_110']
[2025-04-24T15:37:08.296+0000] {standard_task_runner.py:105} INFO - Job 101: Subtask load_data_to_snowflake
[2025-04-24T15:37:08.316+0000] {task_command.py:467} INFO - Running <TaskInstance: airflow_lab.load_data_to_snowflake manual__2025-04-24T15:37:00.247492+00:00 [running]> on host 7ce975cba66d
[2025-04-24T15:37:08.389+0000] {taskinstance.py:3131} INFO - Exporting env vars: AIRFLOW_CTX_DAG_OWNER='***' AIRFLOW_CTX_DAG_ID='***_lab' AIRFLOW_CTX_TASK_ID='load_data_to_snowflake' AIRFLOW_CTX_EXECUTION_DATE='2025-04-24T15:37:00.247492+00:00' AIRFLOW_CTX_TRY_NUMBER='1' AIRFLOW_CTX_DAG_RUN_ID='manual__2025-04-24T15:37:00.247492+00:00'
[2025-04-24T15:37:08.390+0000] {taskinstance.py:731} INFO - ::endgroup::
[2025-04-24T15:37:08.396+0000] {base.py:84} INFO - Retrieving connection 'snowflake_default'
[2025-04-24T15:37:08.397+0000] {connection.py:413} INFO - Snowflake Connector for Python Version: 3.12.2, Python Version: 3.12.6, Platform: Linux-6.10.14-linuxkit-aarch64-with-glibc2.36
[2025-04-24T15:37:08.397+0000] {connection.py:1196} INFO - Connecting to GLOBAL Snowflake domain
[2025-04-24T15:37:08.398+0000] {connection.py:1277} INFO - This connection is in OCSP Fail Open Mode. TLS Certificates would be checked for validity and revocation status. Any other Certificate Revocation related exceptions or OCSP Responder failures would be disregarded in favor of connectivity.
[2025-04-24T15:37:08.724+0000] {logging_mixin.py:190} INFO - New data columns: ['ID', 'Full_Name', 'Gender', 'Date_Time', 'Q01', 'Q02', 'Q03', 'Q04', 'Q05', 'Q06', 'Q07', 'Q08', 'Q09', 'Q10', 'Q11', 'Q12', 'Q13']
[2025-04-24T15:37:09.067+0000] {taskinstance.py:3310} ERROR - Task failed with exception
Traceback (most recent call last):
  File "/home/airflow/.local/lib/python3.12/site-packages/airflow/models/taskinstance.py", line 767, in _execute_task
    result = _execute_callable(context=context, **execute_callable_kwargs)
             ^^^^^^^^^^^^^^^^^^^^^^^^^^^^^^^^^^^^^^^^^^^^^^^^^^^^^^^^^^^^^
  File "/home/airflow/.local/lib/python3.12/site-packages/airflow/models/taskinstance.py", line 733, in _execute_callable
    return ExecutionCallableRunner(
           ^^^^^^^^^^^^^^^^^^^^^^^^
  File "/home/airflow/.local/lib/python3.12/site-packages/airflow/utils/operator_helpers.py", line 252, in run
    return self.func(*args, **kwargs)
           ^^^^^^^^^^^^^^^^^^^^^^^^^^
  File "/home/airflow/.local/lib/python3.12/site-packages/airflow/models/baseoperator.py", line 406, in wrapper
    return func(self, *args, **kwargs)
           ^^^^^^^^^^^^^^^^^^^^^^^^^^^
  File "/home/airflow/.local/lib/python3.12/site-packages/airflow/decorators/base.py", line 266, in execute
    return_value = super().execute(context)
                   ^^^^^^^^^^^^^^^^^^^^^^^^
  File "/home/airflow/.local/lib/python3.12/site-packages/airflow/models/baseoperator.py", line 406, in wrapper
    return func(self, *args, **kwargs)
           ^^^^^^^^^^^^^^^^^^^^^^^^^^^
  File "/home/airflow/.local/lib/python3.12/site-packages/airflow/operators/python.py", line 238, in execute
    return_value = self.execute_callable()
                   ^^^^^^^^^^^^^^^^^^^^^^^
  File "/home/airflow/.local/lib/python3.12/site-packages/airflow/operators/python.py", line 256, in execute_callable
    return runner.run(*self.op_args, **self.op_kwargs)
           ^^^^^^^^^^^^^^^^^^^^^^^^^^^^^^^^^^^^^^^^^^^
  File "/home/airflow/.local/lib/python3.12/site-packages/airflow/utils/operator_helpers.py", line 252, in run
    return self.func(*args, **kwargs)
           ^^^^^^^^^^^^^^^^^^^^^^^^^^
  File "/opt/airflow/dags/elt.py", line 105, in load_data_to_snowflake
    cur.execute(f"""INSERT INTO {TABLE_NAME}
  File "/home/airflow/.local/lib/python3.12/site-packages/snowflake/connector/cursor.py", line 1087, in execute
    Error.errorhandler_wrapper(self.connection, self, error_class, errvalue)
  File "/home/airflow/.local/lib/python3.12/site-packages/snowflake/connector/errors.py", line 284, in errorhandler_wrapper
    handed_over = Error.hand_to_other_handler(
                  ^^^^^^^^^^^^^^^^^^^^^^^^^^^^
  File "/home/airflow/.local/lib/python3.12/site-packages/snowflake/connector/errors.py", line 339, in hand_to_other_handler
    cursor.errorhandler(connection, cursor, error_class, error_value)
  File "/home/airflow/.local/lib/python3.12/site-packages/snowflake/connector/errors.py", line 215, in default_errorhandler
    raise error_class(
snowflake.connector.errors.ProgrammingError: 100038 (22018): 01bbe7e9-3201-913f-000c-b6c600054f56: Numeric value 'ID' is not recognized
[2025-04-24T15:37:09.077+0000] {taskinstance.py:1225} INFO - Marking task as FAILED. dag_id=***_lab, task_id=load_data_to_snowflake, run_id=manual__2025-04-24T15:37:00.247492+00:00, execution_date=20250424T153700, start_date=20250424T153708, end_date=20250424T153709
[2025-04-24T15:37:09.084+0000] {taskinstance.py:340} INFO - ::group::Post task execution logs
[2025-04-24T15:37:09.084+0000] {standard_task_runner.py:124} ERROR - Failed to execute job 101 for task load_data_to_snowflake (100038 (22018): 01bbe7e9-3201-913f-000c-b6c600054f56: Numeric value 'ID' is not recognized; 1465)
Traceback (most recent call last):
  File "/home/airflow/.local/lib/python3.12/site-packages/airflow/task/task_runner/standard_task_runner.py", line 117, in _start_by_fork
    ret = args.func(args, dag=self.dag)
          ^^^^^^^^^^^^^^^^^^^^^^^^^^^^^
  File "/home/airflow/.local/lib/python3.12/site-packages/airflow/cli/cli_config.py", line 49, in command
    return func(*args, **kwargs)
           ^^^^^^^^^^^^^^^^^^^^^
  File "/home/airflow/.local/lib/python3.12/site-packages/airflow/utils/cli.py", line 115, in wrapper
    return f(*args, **kwargs)
           ^^^^^^^^^^^^^^^^^^
  File "/home/airflow/.local/lib/python3.12/site-packages/airflow/cli/commands/task_command.py", line 483, in task_run
    task_return_code = _run_task_by_selected_method(args, _dag, ti)
                       ^^^^^^^^^^^^^^^^^^^^^^^^^^^^^^^^^^^^^^^^^^^^
  File "/home/airflow/.local/lib/python3.12/site-packages/airflow/cli/commands/task_command.py", line 256, in _run_task_by_selected_method
    return _run_raw_task(args, ti)
           ^^^^^^^^^^^^^^^^^^^^^^^
  File "/home/airflow/.local/lib/python3.12/site-packages/airflow/cli/commands/task_command.py", line 341, in _run_raw_task
    return ti._run_raw_task(
           ^^^^^^^^^^^^^^^^^
  File "/home/airflow/.local/lib/python3.12/site-packages/airflow/utils/session.py", line 97, in wrapper
    return func(*args, session=session, **kwargs)
           ^^^^^^^^^^^^^^^^^^^^^^^^^^^^^^^^^^^^^^
  File "/home/airflow/.local/lib/python3.12/site-packages/airflow/models/taskinstance.py", line 3004, in _run_raw_task
    return _run_raw_task(
           ^^^^^^^^^^^^^^
  File "/home/airflow/.local/lib/python3.12/site-packages/airflow/models/taskinstance.py", line 273, in _run_raw_task
    TaskInstance._execute_task_with_callbacks(
  File "/home/airflow/.local/lib/python3.12/site-packages/airflow/models/taskinstance.py", line 3158, in _execute_task_with_callbacks
    result = self._execute_task(context, task_orig)
             ^^^^^^^^^^^^^^^^^^^^^^^^^^^^^^^^^^^^^^
  File "/home/airflow/.local/lib/python3.12/site-packages/airflow/models/taskinstance.py", line 3182, in _execute_task
    return _execute_task(self, context, task_orig)
           ^^^^^^^^^^^^^^^^^^^^^^^^^^^^^^^^^^^^^^^
  File "/home/airflow/.local/lib/python3.12/site-packages/airflow/models/taskinstance.py", line 767, in _execute_task
    result = _execute_callable(context=context, **execute_callable_kwargs)
             ^^^^^^^^^^^^^^^^^^^^^^^^^^^^^^^^^^^^^^^^^^^^^^^^^^^^^^^^^^^^^
  File "/home/airflow/.local/lib/python3.12/site-packages/airflow/models/taskinstance.py", line 733, in _execute_callable
    return ExecutionCallableRunner(
           ^^^^^^^^^^^^^^^^^^^^^^^^
  File "/home/airflow/.local/lib/python3.12/site-packages/airflow/utils/operator_helpers.py", line 252, in run
    return self.func(*args, **kwargs)
           ^^^^^^^^^^^^^^^^^^^^^^^^^^
  File "/home/airflow/.local/lib/python3.12/site-packages/airflow/models/baseoperator.py", line 406, in wrapper
    return func(self, *args, **kwargs)
           ^^^^^^^^^^^^^^^^^^^^^^^^^^^
  File "/home/airflow/.local/lib/python3.12/site-packages/airflow/decorators/base.py", line 266, in execute
    return_value = super().execute(context)
                   ^^^^^^^^^^^^^^^^^^^^^^^^
  File "/home/airflow/.local/lib/python3.12/site-packages/airflow/models/baseoperator.py", line 406, in wrapper
    return func(self, *args, **kwargs)
           ^^^^^^^^^^^^^^^^^^^^^^^^^^^
  File "/home/airflow/.local/lib/python3.12/site-packages/airflow/operators/python.py", line 238, in execute
    return_value = self.execute_callable()
                   ^^^^^^^^^^^^^^^^^^^^^^^
  File "/home/airflow/.local/lib/python3.12/site-packages/airflow/operators/python.py", line 256, in execute_callable
    return runner.run(*self.op_args, **self.op_kwargs)
           ^^^^^^^^^^^^^^^^^^^^^^^^^^^^^^^^^^^^^^^^^^^
  File "/home/airflow/.local/lib/python3.12/site-packages/airflow/utils/operator_helpers.py", line 252, in run
    return self.func(*args, **kwargs)
           ^^^^^^^^^^^^^^^^^^^^^^^^^^
  File "/opt/airflow/dags/elt.py", line 105, in load_data_to_snowflake
    cur.execute(f"""INSERT INTO {TABLE_NAME}
  File "/home/airflow/.local/lib/python3.12/site-packages/snowflake/connector/cursor.py", line 1087, in execute
    Error.errorhandler_wrapper(self.connection, self, error_class, errvalue)
  File "/home/airflow/.local/lib/python3.12/site-packages/snowflake/connector/errors.py", line 284, in errorhandler_wrapper
    handed_over = Error.hand_to_other_handler(
                  ^^^^^^^^^^^^^^^^^^^^^^^^^^^^
  File "/home/airflow/.local/lib/python3.12/site-packages/snowflake/connector/errors.py", line 339, in hand_to_other_handler
    cursor.errorhandler(connection, cursor, error_class, error_value)
  File "/home/airflow/.local/lib/python3.12/site-packages/snowflake/connector/errors.py", line 215, in default_errorhandler
    raise error_class(
snowflake.connector.errors.ProgrammingError: 100038 (22018): 01bbe7e9-3201-913f-000c-b6c600054f56: Numeric value 'ID' is not recognized
[2025-04-24T15:37:09.116+0000] {local_task_job_runner.py:266} INFO - Task exited with return code 1
[2025-04-24T15:37:09.126+0000] {taskinstance.py:3900} INFO - 0 downstream tasks scheduled from follow-on schedule check
[2025-04-24T15:37:09.127+0000] {local_task_job_runner.py:245} INFO - ::endgroup::
