[2025-04-22T14:08:56.308+0000] {local_task_job_runner.py:123} INFO - ::group::Pre task execution logs
[2025-04-22T14:08:56.316+0000] {taskinstance.py:2612} INFO - Dependencies all met for dep_context=non-requeueable deps ti=<TaskInstance: airflow_lab.create_table manual__2025-04-22T14:08:53.993490+00:00 [queued]>
[2025-04-22T14:08:56.320+0000] {taskinstance.py:2612} INFO - Dependencies all met for dep_context=requeueable deps ti=<TaskInstance: airflow_lab.create_table manual__2025-04-22T14:08:53.993490+00:00 [queued]>
[2025-04-22T14:08:56.320+0000] {taskinstance.py:2865} INFO - Starting attempt 1 of 1
[2025-04-22T14:08:56.325+0000] {taskinstance.py:2888} INFO - Executing <Task(_PythonDecoratedOperator): create_table> on 2025-04-22 14:08:53.993490+00:00
[2025-04-22T14:08:56.330+0000] {warnings.py:112} WARNING - /home/***/.local/lib/python3.12/site-packages/***/task/task_runner/standard_task_runner.py:70: DeprecationWarning: This process (pid=9080) is multi-threaded, use of fork() may lead to deadlocks in the child.
  pid = os.fork()

[2025-04-22T14:08:56.331+0000] {standard_task_runner.py:72} INFO - Started process 9082 to run task
[2025-04-22T14:08:56.331+0000] {standard_task_runner.py:104} INFO - Running: ['***', 'tasks', 'run', '***_lab', 'create_table', 'manual__2025-04-22T14:08:53.993490+00:00', '--job-id', '6', '--raw', '--subdir', 'DAGS_FOLDER/elt.py', '--cfg-path', '/tmp/tmpao8cr7q5']
[2025-04-22T14:08:56.332+0000] {standard_task_runner.py:105} INFO - Job 6: Subtask create_table
[2025-04-22T14:08:56.357+0000] {task_command.py:467} INFO - Running <TaskInstance: airflow_lab.create_table manual__2025-04-22T14:08:53.993490+00:00 [running]> on host bf7172c0a1ab
[2025-04-22T14:08:56.391+0000] {taskinstance.py:3131} INFO - Exporting env vars: AIRFLOW_CTX_DAG_OWNER='***' AIRFLOW_CTX_DAG_ID='***_lab' AIRFLOW_CTX_TASK_ID='create_table' AIRFLOW_CTX_EXECUTION_DATE='2025-04-22T14:08:53.993490+00:00' AIRFLOW_CTX_TRY_NUMBER='1' AIRFLOW_CTX_DAG_RUN_ID='manual__2025-04-22T14:08:53.993490+00:00'
[2025-04-22T14:08:56.394+0000] {taskinstance.py:731} INFO - ::endgroup::
[2025-04-22T14:08:56.395+0000] {logging_mixin.py:190} INFO - Creating table: test_table
[2025-04-22T14:08:56.400+0000] {base.py:84} INFO - Retrieving connection 'snowflake_default'
[2025-04-22T14:08:56.401+0000] {connection.py:413} INFO - Snowflake Connector for Python Version: 3.12.2, Python Version: 3.12.6, Platform: Linux-6.10.14-linuxkit-aarch64-with-glibc2.36
[2025-04-22T14:08:56.401+0000] {connection.py:1196} INFO - Connecting to GLOBAL Snowflake domain
[2025-04-22T14:08:56.402+0000] {connection.py:1277} INFO - This connection is in OCSP Fail Open Mode. TLS Certificates would be checked for validity and revocation status. Any other Certificate Revocation related exceptions or OCSP Responder failures would be disregarded in favor of connectivity.
[2025-04-22T14:08:57.435+0000] {taskinstance.py:3310} ERROR - Task failed with exception
Traceback (most recent call last):
  File "/home/airflow/.local/lib/python3.12/site-packages/airflow/models/taskinstance.py", line 767, in _execute_task
    result = _execute_callable(context=context, **execute_callable_kwargs)
             ^^^^^^^^^^^^^^^^^^^^^^^^^^^^^^^^^^^^^^^^^^^^^^^^^^^^^^^^^^^^^
  File "/home/airflow/.local/lib/python3.12/site-packages/airflow/models/taskinstance.py", line 733, in _execute_callable
    return ExecutionCallableRunner(
           ^^^^^^^^^^^^^^^^^^^^^^^^
  File "/home/airflow/.local/lib/python3.12/site-packages/airflow/utils/operator_helpers.py", line 252, in run
    return self.func(*args, **kwargs)
           ^^^^^^^^^^^^^^^^^^^^^^^^^^
  File "/home/airflow/.local/lib/python3.12/site-packages/airflow/models/baseoperator.py", line 406, in wrapper
    return func(self, *args, **kwargs)
           ^^^^^^^^^^^^^^^^^^^^^^^^^^^
  File "/home/airflow/.local/lib/python3.12/site-packages/airflow/decorators/base.py", line 266, in execute
    return_value = super().execute(context)
                   ^^^^^^^^^^^^^^^^^^^^^^^^
  File "/home/airflow/.local/lib/python3.12/site-packages/airflow/models/baseoperator.py", line 406, in wrapper
    return func(self, *args, **kwargs)
           ^^^^^^^^^^^^^^^^^^^^^^^^^^^
  File "/home/airflow/.local/lib/python3.12/site-packages/airflow/operators/python.py", line 238, in execute
    return_value = self.execute_callable()
                   ^^^^^^^^^^^^^^^^^^^^^^^
  File "/home/airflow/.local/lib/python3.12/site-packages/airflow/operators/python.py", line 256, in execute_callable
    return runner.run(*self.op_args, **self.op_kwargs)
           ^^^^^^^^^^^^^^^^^^^^^^^^^^^^^^^^^^^^^^^^^^^
  File "/home/airflow/.local/lib/python3.12/site-packages/airflow/utils/operator_helpers.py", line 252, in run
    return self.func(*args, **kwargs)
           ^^^^^^^^^^^^^^^^^^^^^^^^^^
  File "/opt/airflow/dags/elt.py", line 59, in create_table
    conn = get_snowflake_connection()
           ^^^^^^^^^^^^^^^^^^^^^^^^^^
  File "/opt/airflow/dags/elt.py", line 43, in get_snowflake_connection
    return snowflake.connector.connect(
           ^^^^^^^^^^^^^^^^^^^^^^^^^^^^
  File "/home/airflow/.local/lib/python3.12/site-packages/snowflake/connector/__init__.py", line 55, in Connect
    return SnowflakeConnection(**kwargs)
           ^^^^^^^^^^^^^^^^^^^^^^^^^^^^^
  File "/home/airflow/.local/lib/python3.12/site-packages/snowflake/connector/connection.py", line 456, in __init__
    self.connect(**kwargs)
  File "/home/airflow/.local/lib/python3.12/site-packages/snowflake/connector/connection.py", line 771, in connect
    self.__open_connection()
  File "/home/airflow/.local/lib/python3.12/site-packages/snowflake/connector/connection.py", line 1099, in __open_connection
    self.authenticate_with_retry(self.auth_class)
  File "/home/airflow/.local/lib/python3.12/site-packages/snowflake/connector/connection.py", line 1386, in authenticate_with_retry
    self._authenticate(auth_instance)
  File "/home/airflow/.local/lib/python3.12/site-packages/snowflake/connector/connection.py", line 1414, in _authenticate
    auth.authenticate(
  File "/home/airflow/.local/lib/python3.12/site-packages/snowflake/connector/auth/_auth.py", line 250, in authenticate
    ret = self._rest._post_request(
          ^^^^^^^^^^^^^^^^^^^^^^^^^
  File "/home/airflow/.local/lib/python3.12/site-packages/snowflake/connector/network.py", line 739, in _post_request
    ret = self.fetch(
          ^^^^^^^^^^^
  File "/home/airflow/.local/lib/python3.12/site-packages/snowflake/connector/network.py", line 854, in fetch
    ret = self._request_exec_wrapper(
          ^^^^^^^^^^^^^^^^^^^^^^^^^^^
  File "/home/airflow/.local/lib/python3.12/site-packages/snowflake/connector/network.py", line 982, in _request_exec_wrapper
    raise e
  File "/home/airflow/.local/lib/python3.12/site-packages/snowflake/connector/network.py", line 904, in _request_exec_wrapper
    return_object = self._request_exec(
                    ^^^^^^^^^^^^^^^^^^^
  File "/home/airflow/.local/lib/python3.12/site-packages/snowflake/connector/network.py", line 1170, in _request_exec
    raise err
  File "/home/airflow/.local/lib/python3.12/site-packages/snowflake/connector/network.py", line 1130, in _request_exec
    raise_failed_request_error(
  File "/home/airflow/.local/lib/python3.12/site-packages/snowflake/connector/network.py", line 230, in raise_failed_request_error
    Error.errorhandler_wrapper(
  File "/home/airflow/.local/lib/python3.12/site-packages/snowflake/connector/errors.py", line 284, in errorhandler_wrapper
    handed_over = Error.hand_to_other_handler(
                  ^^^^^^^^^^^^^^^^^^^^^^^^^^^^
  File "/home/airflow/.local/lib/python3.12/site-packages/snowflake/connector/errors.py", line 342, in hand_to_other_handler
    connection.errorhandler(connection, cursor, error_class, error_value)
  File "/home/airflow/.local/lib/python3.12/site-packages/snowflake/connector/errors.py", line 215, in default_errorhandler
    raise error_class(
snowflake.connector.errors.InterfaceError: 250003 (08001): None: 404 Not Found: post https://accountZFLRNBO-YT37108.snowflakecomputing.com:443/session/v1/login-request?request_id=13f1add5-660e-442f-a494-9200d2388808&databaseName=CAPSTONE_PROJECT_TB&schemaName=TB_PATIENT_SYMPTOMS&request_guid=457a8abe-2cb0-4194-876b-99a918853917
[2025-04-22T14:08:57.446+0000] {taskinstance.py:1225} INFO - Marking task as FAILED. dag_id=***_lab, task_id=create_table, run_id=manual__2025-04-22T14:08:53.993490+00:00, execution_date=20250422T140853, start_date=20250422T140856, end_date=20250422T140857
[2025-04-22T14:08:57.453+0000] {taskinstance.py:340} INFO - ::group::Post task execution logs
[2025-04-22T14:08:57.454+0000] {standard_task_runner.py:124} ERROR - Failed to execute job 6 for task create_table (250003 (08001): None: 404 Not Found: post https://accountZFLRNBO-YT37108.snowflakecomputing.com:443/session/v1/login-request?request_id=13f1add5-660e-442f-a494-9200d2388808&databaseName=CAPSTONE_PROJECT_TB&schemaName=TB_PATIENT_SYMPTOMS&request_guid=457a8abe-2cb0-4194-876b-99a918853917; 9082)
Traceback (most recent call last):
  File "/home/airflow/.local/lib/python3.12/site-packages/airflow/task/task_runner/standard_task_runner.py", line 117, in _start_by_fork
    ret = args.func(args, dag=self.dag)
          ^^^^^^^^^^^^^^^^^^^^^^^^^^^^^
  File "/home/airflow/.local/lib/python3.12/site-packages/airflow/cli/cli_config.py", line 49, in command
    return func(*args, **kwargs)
           ^^^^^^^^^^^^^^^^^^^^^
  File "/home/airflow/.local/lib/python3.12/site-packages/airflow/utils/cli.py", line 115, in wrapper
    return f(*args, **kwargs)
           ^^^^^^^^^^^^^^^^^^
  File "/home/airflow/.local/lib/python3.12/site-packages/airflow/cli/commands/task_command.py", line 483, in task_run
    task_return_code = _run_task_by_selected_method(args, _dag, ti)
                       ^^^^^^^^^^^^^^^^^^^^^^^^^^^^^^^^^^^^^^^^^^^^
  File "/home/airflow/.local/lib/python3.12/site-packages/airflow/cli/commands/task_command.py", line 256, in _run_task_by_selected_method
    return _run_raw_task(args, ti)
           ^^^^^^^^^^^^^^^^^^^^^^^
  File "/home/airflow/.local/lib/python3.12/site-packages/airflow/cli/commands/task_command.py", line 341, in _run_raw_task
    return ti._run_raw_task(
           ^^^^^^^^^^^^^^^^^
  File "/home/airflow/.local/lib/python3.12/site-packages/airflow/utils/session.py", line 97, in wrapper
    return func(*args, session=session, **kwargs)
           ^^^^^^^^^^^^^^^^^^^^^^^^^^^^^^^^^^^^^^
  File "/home/airflow/.local/lib/python3.12/site-packages/airflow/models/taskinstance.py", line 3004, in _run_raw_task
    return _run_raw_task(
           ^^^^^^^^^^^^^^
  File "/home/airflow/.local/lib/python3.12/site-packages/airflow/models/taskinstance.py", line 273, in _run_raw_task
    TaskInstance._execute_task_with_callbacks(
  File "/home/airflow/.local/lib/python3.12/site-packages/airflow/models/taskinstance.py", line 3158, in _execute_task_with_callbacks
    result = self._execute_task(context, task_orig)
             ^^^^^^^^^^^^^^^^^^^^^^^^^^^^^^^^^^^^^^
  File "/home/airflow/.local/lib/python3.12/site-packages/airflow/models/taskinstance.py", line 3182, in _execute_task
    return _execute_task(self, context, task_orig)
           ^^^^^^^^^^^^^^^^^^^^^^^^^^^^^^^^^^^^^^^
  File "/home/airflow/.local/lib/python3.12/site-packages/airflow/models/taskinstance.py", line 767, in _execute_task
    result = _execute_callable(context=context, **execute_callable_kwargs)
             ^^^^^^^^^^^^^^^^^^^^^^^^^^^^^^^^^^^^^^^^^^^^^^^^^^^^^^^^^^^^^
  File "/home/airflow/.local/lib/python3.12/site-packages/airflow/models/taskinstance.py", line 733, in _execute_callable
    return ExecutionCallableRunner(
           ^^^^^^^^^^^^^^^^^^^^^^^^
  File "/home/airflow/.local/lib/python3.12/site-packages/airflow/utils/operator_helpers.py", line 252, in run
    return self.func(*args, **kwargs)
           ^^^^^^^^^^^^^^^^^^^^^^^^^^
  File "/home/airflow/.local/lib/python3.12/site-packages/airflow/models/baseoperator.py", line 406, in wrapper
    return func(self, *args, **kwargs)
           ^^^^^^^^^^^^^^^^^^^^^^^^^^^
  File "/home/airflow/.local/lib/python3.12/site-packages/airflow/decorators/base.py", line 266, in execute
    return_value = super().execute(context)
                   ^^^^^^^^^^^^^^^^^^^^^^^^
  File "/home/airflow/.local/lib/python3.12/site-packages/airflow/models/baseoperator.py", line 406, in wrapper
    return func(self, *args, **kwargs)
           ^^^^^^^^^^^^^^^^^^^^^^^^^^^
  File "/home/airflow/.local/lib/python3.12/site-packages/airflow/operators/python.py", line 238, in execute
    return_value = self.execute_callable()
                   ^^^^^^^^^^^^^^^^^^^^^^^
  File "/home/airflow/.local/lib/python3.12/site-packages/airflow/operators/python.py", line 256, in execute_callable
    return runner.run(*self.op_args, **self.op_kwargs)
           ^^^^^^^^^^^^^^^^^^^^^^^^^^^^^^^^^^^^^^^^^^^
  File "/home/airflow/.local/lib/python3.12/site-packages/airflow/utils/operator_helpers.py", line 252, in run
    return self.func(*args, **kwargs)
           ^^^^^^^^^^^^^^^^^^^^^^^^^^
  File "/opt/airflow/dags/elt.py", line 59, in create_table
    conn = get_snowflake_connection()
           ^^^^^^^^^^^^^^^^^^^^^^^^^^
  File "/opt/airflow/dags/elt.py", line 43, in get_snowflake_connection
    return snowflake.connector.connect(
           ^^^^^^^^^^^^^^^^^^^^^^^^^^^^
  File "/home/airflow/.local/lib/python3.12/site-packages/snowflake/connector/__init__.py", line 55, in Connect
    return SnowflakeConnection(**kwargs)
           ^^^^^^^^^^^^^^^^^^^^^^^^^^^^^
  File "/home/airflow/.local/lib/python3.12/site-packages/snowflake/connector/connection.py", line 456, in __init__
    self.connect(**kwargs)
  File "/home/airflow/.local/lib/python3.12/site-packages/snowflake/connector/connection.py", line 771, in connect
    self.__open_connection()
  File "/home/airflow/.local/lib/python3.12/site-packages/snowflake/connector/connection.py", line 1099, in __open_connection
    self.authenticate_with_retry(self.auth_class)
  File "/home/airflow/.local/lib/python3.12/site-packages/snowflake/connector/connection.py", line 1386, in authenticate_with_retry
    self._authenticate(auth_instance)
  File "/home/airflow/.local/lib/python3.12/site-packages/snowflake/connector/connection.py", line 1414, in _authenticate
    auth.authenticate(
  File "/home/airflow/.local/lib/python3.12/site-packages/snowflake/connector/auth/_auth.py", line 250, in authenticate
    ret = self._rest._post_request(
          ^^^^^^^^^^^^^^^^^^^^^^^^^
  File "/home/airflow/.local/lib/python3.12/site-packages/snowflake/connector/network.py", line 739, in _post_request
    ret = self.fetch(
          ^^^^^^^^^^^
  File "/home/airflow/.local/lib/python3.12/site-packages/snowflake/connector/network.py", line 854, in fetch
    ret = self._request_exec_wrapper(
          ^^^^^^^^^^^^^^^^^^^^^^^^^^^
  File "/home/airflow/.local/lib/python3.12/site-packages/snowflake/connector/network.py", line 982, in _request_exec_wrapper
    raise e
  File "/home/airflow/.local/lib/python3.12/site-packages/snowflake/connector/network.py", line 904, in _request_exec_wrapper
    return_object = self._request_exec(
                    ^^^^^^^^^^^^^^^^^^^
  File "/home/airflow/.local/lib/python3.12/site-packages/snowflake/connector/network.py", line 1170, in _request_exec
    raise err
  File "/home/airflow/.local/lib/python3.12/site-packages/snowflake/connector/network.py", line 1130, in _request_exec
    raise_failed_request_error(
  File "/home/airflow/.local/lib/python3.12/site-packages/snowflake/connector/network.py", line 230, in raise_failed_request_error
    Error.errorhandler_wrapper(
  File "/home/airflow/.local/lib/python3.12/site-packages/snowflake/connector/errors.py", line 284, in errorhandler_wrapper
    handed_over = Error.hand_to_other_handler(
                  ^^^^^^^^^^^^^^^^^^^^^^^^^^^^
  File "/home/airflow/.local/lib/python3.12/site-packages/snowflake/connector/errors.py", line 342, in hand_to_other_handler
    connection.errorhandler(connection, cursor, error_class, error_value)
  File "/home/airflow/.local/lib/python3.12/site-packages/snowflake/connector/errors.py", line 215, in default_errorhandler
    raise error_class(
snowflake.connector.errors.InterfaceError: 250003 (08001): None: 404 Not Found: post https://accountZFLRNBO-YT37108.snowflakecomputing.com:443/session/v1/login-request?request_id=13f1add5-660e-442f-a494-9200d2388808&databaseName=CAPSTONE_PROJECT_TB&schemaName=TB_PATIENT_SYMPTOMS&request_guid=457a8abe-2cb0-4194-876b-99a918853917
[2025-04-22T14:08:57.479+0000] {local_task_job_runner.py:266} INFO - Task exited with return code 1
[2025-04-22T14:08:57.488+0000] {taskinstance.py:3900} INFO - 0 downstream tasks scheduled from follow-on schedule check
[2025-04-22T14:08:57.489+0000] {local_task_job_runner.py:245} INFO - ::endgroup::
